Workbook

Sheet Messages
A1: Messages Draft
A3: =IF('Profit & Loss'!A6>=TODAY(),"Looking for friendly players to join the following game: " & CHAR(10) & CHAR(10) & "Date: " & TEXT('Profit & Loss'!A6,"dd mmm yyy") & ", " & 'Profit & Loss'!B6 & CHAR(10) & "Time: " & TEXT('Profit & Loss'!C6, "hh:mm AM/PM") & " - " & TEXT('Profit & Loss'!D6, "hh:mm AM/PM") & CHAR(10) & "Venue: " & 'Profit & Loss'!E6 & CHAR(10) & "Level: HB - LI" & CHAR(10) & "Cost: $" & 'Profit & Loss'!O6 & " per pax" & CHAR(10) & "Max " & 'Profit & Loss'!I6*6 & " pax," & " (" & 'Profit & Loss'!I6 & " courts)" & CHAR(10) & CHAR(10) & "RSL Ultimate shuttles provided" & CHAR(10) & CHAR(10) & "PM if interested, thank you!"," ")
A4: =IF('Profit & Loss'!A7>=TODAY(),"Looking for friendly players to join the following game: " & CHAR(10) & CHAR(10) & "Date: " & TEXT('Profit & Loss'!A7,"dd mmm yyy") & ", " & 'Profit & Loss'!B7 & CHAR(10) & "Time: " & TEXT('Profit & Loss'!C7, "hh:mm AM/PM") & " - " & TEXT('Profit & Loss'!D7, "hh:mm AM/PM") & CHAR(10) & "Venue: " & 'Profit & Loss'!E7 & CHAR(10) & "Level: HB - LI" & CHAR(10) & "Cost: $" & 'Profit & Loss'!O7 & " per pax" & CHAR(10) & "Max " & 'Profit & Loss'!I7*6 & " pax," & " (" & 'Profit & Loss'!I7 & " courts)" & CHAR(10) & CHAR(10) & "RSL Ultimate shuttles provided" & CHAR(10) & CHAR(10) & "PM if interested, thank you!"," ")
A5: =IF('Profit & Loss'!A8>=TODAY(),"Looking for friendly players to join the following game: " & CHAR(10) & CHAR(10) & "Date: " & TEXT('Profit & Loss'!A8,"dd mmm yyy") & ", " & 'Profit & Loss'!B8 & CHAR(10) & "Time: " & TEXT('Profit & Loss'!C8, "hh:mm AM/PM") & " - " & TEXT('Profit & Loss'!D8, "hh:mm AM/PM") & CHAR(10) & "Venue: " & 'Profit & Loss'!E8 & CHAR(10) & "Level: HB - LI" & CHAR(10) & "Cost: $" & 'Profit & Loss'!O8 & " per pax" & CHAR(10) & "Max " & 'Profit & Loss'!I8*6 & " pax," & " (" & 'Profit & Loss'!I8 & " courts)" & CHAR(10) & CHAR(10) & "RSL Ultimate shuttles provided" & CHAR(10) & CHAR(10) & "PM if interested, thank you!"," ")
A6: =IF('Profit & Loss'!A9>=TODAY(),"Looking for friendly players to join the following game: " & CHAR(10) & CHAR(10) & "Date: " & TEXT('Profit & Loss'!A9,"dd mmm yyy") & ", " & 'Profit & Loss'!B9 & CHAR(10) & "Time: " & TEXT('Profit & Loss'!C9, "hh:mm AM/PM") & " - " & TEXT('Profit & Loss'!D9, "hh:mm AM/PM") & CHAR(10) & "Venue: " & 'Profit & Loss'!E9 & CHAR(10) & "Level: HB - LI" & CHAR(10) & "Cost: $" & 'Profit & Loss'!O9 & " per pax" & CHAR(10) & "Max " & 'Profit & Loss'!I9*6 & " pax," & " (" & 'Profit & Loss'!I9 & " courts)" & CHAR(10) & CHAR(10) & "RSL Ultimate shuttles provided" & CHAR(10) & CHAR(10) & "PM if interested, thank you!"," ")
A7: =IF('Profit & Loss'!A10>=TODAY(),"Looking for friendly players to join the following game: " & CHAR(10) & CHAR(10) & "Date: " & TEXT('Profit & Loss'!A10,"dd mmm yyy") & ", " & 'Profit & Loss'!B10 & CHAR(10) & "Time: " & TEXT('Profit & Loss'!C10, "hh:mm AM/PM") & " - " & TEXT('Profit & Loss'!D10, "hh:mm AM/PM") & CHAR(10) & "Venue: " & 'Profit & Loss'!E10 & CHAR(10) & "Level: HB - LI" & CHAR(10) & "Cost: $" & 'Profit & Loss'!O10 & " per pax" & CHAR(10) & "Max " & 'Profit & Loss'!I10*6 & " pax," & " (" & 'Profit & Loss'!I10 & " courts)" & CHAR(10) & CHAR(10) & "RSL Ultimate shuttles provided" & CHAR(10) & CHAR(10) & "PM if interested, thank you!"," ")
A8: =IF('Profit & Loss'!A11>=TODAY(),"Looking for friendly players to join the following game: " & CHAR(10) & CHAR(10) & "Date: " & TEXT('Profit & Loss'!A11,"dd mmm yyy") & ", " & 'Profit & Loss'!B11 & CHAR(10) & "Time: " & TEXT('Profit & Loss'!C11, "hh:mm AM/PM") & " - " & TEXT('Profit & Loss'!D11, "hh:mm AM/PM") & CHAR(10) & "Venue: " & 'Profit & Loss'!E11 & CHAR(10) & "Level: HB - LI" & CHAR(10) & "Cost: $" & 'Profit & Loss'!O11 & " per pax" & CHAR(10) & "Max " & 'Profit & Loss'!I11*6 & " pax," & " (" & 'Profit & Loss'!I11 & " courts)" & CHAR(10) & CHAR(10) & "RSL Ultimate shuttles provided" & CHAR(10) & CHAR(10) & "PM if interested, thank you!"," ")
A9: =IF('Profit & Loss'!A12>=TODAY(),"Looking for friendly players to join the following game: " & CHAR(10) & CHAR(10) & "Date: " & TEXT('Profit & Loss'!A12,"dd mmm yyy") & ", " & 'Profit & Loss'!B12 & CHAR(10) & "Time: " & TEXT('Profit & Loss'!C12, "hh:mm AM/PM") & " - " & TEXT('Profit & Loss'!D12, "hh:mm AM/PM") & CHAR(10) & "Venue: " & 'Profit & Loss'!E12 & CHAR(10) & "Level: HB - LI" & CHAR(10) & "Cost: $" & 'Profit & Loss'!O12 & " per pax" & CHAR(10) & "Max " & 'Profit & Loss'!I12*6 & " pax," & " (" & 'Profit & Loss'!I12 & " courts)" & CHAR(10) & CHAR(10) & "RSL Ultimate shuttles provided" & CHAR(10) & CHAR(10) & "PM if interested, thank you!"," ")
A10: =IF('Profit & Loss'!A13>=TODAY(),"Looking for friendly players to join the following game: " & CHAR(10) & CHAR(10) & "Date: " & TEXT('Profit & Loss'!A13,"dd mmm yyy") & ", " & 'Profit & Loss'!B13 & CHAR(10) & "Time: " & TEXT('Profit & Loss'!C13, "hh:mm AM/PM") & " - " & TEXT('Profit & Loss'!D13, "hh:mm AM/PM") & CHAR(10) & "Venue: " & 'Profit & Loss'!E13 & CHAR(10) & "Level: HB - LI" & CHAR(10) & "Cost: $" & 'Profit & Loss'!O13 & " per pax" & CHAR(10) & "Max " & 'Profit & Loss'!I13*6 & " pax," & " (" & 'Profit & Loss'!I13 & " courts)" & CHAR(10) & CHAR(10) & "RSL Ultimate shuttles provided" & CHAR(10) & CHAR(10) & "PM if interested, thank you!"," ")
A11: =IF('Profit & Loss'!A14>=TODAY(),"Looking for friendly players to join the following game: " & CHAR(10) & CHAR(10) & "Date: " & TEXT('Profit & Loss'!A14,"dd mmm yyy") & ", " & 'Profit & Loss'!B14 & CHAR(10) & "Time: " & TEXT('Profit & Loss'!C14, "hh:mm AM/PM") & " - " & TEXT('Profit & Loss'!D14, "hh:mm AM/PM") & CHAR(10) & "Venue: " & 'Profit & Loss'!E14 & CHAR(10) & "Level: HB - LI" & CHAR(10) & "Cost: $" & 'Profit & Loss'!O14 & " per pax" & CHAR(10) & "Max " & 'Profit & Loss'!I14*6 & " pax," & " (" & 'Profit & Loss'!I14 & " courts)" & CHAR(10) & CHAR(10) & "RSL Ultimate shuttles provided" & CHAR(10) & CHAR(10) & "PM if interested, thank you!"," ")
A12: =IF('Profit & Loss'!A15>=TODAY(),"Looking for friendly players to join the following game: " & CHAR(10) & CHAR(10) & "Date: " & TEXT('Profit & Loss'!A15,"dd mmm yyy") & ", " & 'Profit & Loss'!B15 & CHAR(10) & "Time: " & TEXT('Profit & Loss'!C15, "hh:mm AM/PM") & " - " & TEXT('Profit & Loss'!D15, "hh:mm AM/PM") & CHAR(10) & "Venue: " & 'Profit & Loss'!E15 & CHAR(10) & "Level: HB - LI" & CHAR(10) & "Cost: $" & 'Profit & Loss'!O15 & " per pax" & CHAR(10) & "Max " & 'Profit & Loss'!I15*6 & " pax," & " (" & 'Profit & Loss'!I15 & " courts)" & CHAR(10) & CHAR(10) & "RSL Ultimate shuttles provided" & CHAR(10) & CHAR(10) & "PM if interested, thank you!"," ")
A13: =IF('Profit & Loss'!A16>=TODAY(),"Looking for friendly players to join the following game: " & CHAR(10) & CHAR(10) & "Date: " & TEXT('Profit & Loss'!A16,"dd mmm yyy") & ", " & 'Profit & Loss'!B16 & CHAR(10) & "Time: " & TEXT('Profit & Loss'!C16, "hh:mm AM/PM") & " - " & TEXT('Profit & Loss'!D16, "hh:mm AM/PM") & CHAR(10) & "Venue: " & 'Profit & Loss'!E16 & CHAR(10) & "Level: HB - LI" & CHAR(10) & "Cost: $" & 'Profit & Loss'!O16 & " per pax" & CHAR(10) & "Max " & 'Profit & Loss'!I16*6 & " pax," & " (" & 'Profit & Loss'!I16 & " courts)" & CHAR(10) & CHAR(10) & "RSL Ultimate shuttles provided" & CHAR(10) & CHAR(10) & "PM if interested, thank you!"," ")
A14: =IF('Profit & Loss'!A17>=TODAY(),"Looking for friendly players to join the following game: " & CHAR(10) & CHAR(10) & "Date: " & TEXT('Profit & Loss'!A17,"dd mmm yyy") & ", " & 'Profit & Loss'!B17 & CHAR(10) & "Time: " & TEXT('Profit & Loss'!C17, "hh:mm AM/PM") & " - " & TEXT('Profit & Loss'!D17, "hh:mm AM/PM") & CHAR(10) & "Venue: " & 'Profit & Loss'!E17 & CHAR(10) & "Level: HB - LI" & CHAR(10) & "Cost: $" & 'Profit & Loss'!O17 & " per pax" & CHAR(10) & "Max " & 'Profit & Loss'!I17*6 & " pax," & " (" & 'Profit & Loss'!I17 & " courts)" & CHAR(10) & CHAR(10) & "RSL Ultimate shuttles provided" & CHAR(10) & CHAR(10) & "PM if interested, thank you!"," ")
A15: =IF('Profit & Loss'!A19>=TODAY(),"Looking for friendly players to join the following game: " & CHAR(10) & CHAR(10) & "Date: " & TEXT('Profit & Loss'!A19,"dd mmm yyy") & ", " & 'Profit & Loss'!B19 & CHAR(10) & "Time: " & TEXT('Profit & Loss'!C19, "hh:mm AM/PM") & " - " & TEXT('Profit & Loss'!D19, "hh:mm AM/PM") & CHAR(10) & "Venue: " & 'Profit & Loss'!E19 & CHAR(10) & "Level: HB - LI" & CHAR(10) & "Cost: $" & 'Profit & Loss'!O19 & " per pax" & CHAR(10) & "Max " & 'Profit & Loss'!I19*6 & " pax," & " (" & 'Profit & Loss'!I19 & " courts)" & CHAR(10) & CHAR(10) & "RSL Ultimate shuttles provided" & CHAR(10) & CHAR(10) & "PM if interested, thank you!"," ")
A16: =IF('Profit & Loss'!A18>=TODAY(),"Looking for friendly players to join the following game: " & CHAR(10) & CHAR(10) & "Date: " & TEXT('Profit & Loss'!A18,"dd mmm yyy") & ", " & 'Profit & Loss'!B18 & CHAR(10) & "Time: " & TEXT('Profit & Loss'!C18, "hh:mm AM/PM") & " - " & TEXT('Profit & Loss'!D18, "hh:mm AM/PM") & CHAR(10) & "Venue: " & 'Profit & Loss'!E18 & CHAR(10) & "Level: HB - LI" & CHAR(10) & "Cost: $" & 'Profit & Loss'!O18 & " per pax" & CHAR(10) & "Max " & 'Profit & Loss'!I18*6 & " pax," & " (" & 'Profit & Loss'!I18 & " courts)" & CHAR(10) & CHAR(10) & "RSL Ultimate shuttles provided" & CHAR(10) & CHAR(10) & "PM if interested, thank you!"," ")
A17: =IF('Profit & Loss'!A20>=TODAY(),"Looking for friendly players to join the following game: " & CHAR(10) & CHAR(10) & "Date: " & TEXT('Profit & Loss'!A20,"dd mmm yyy") & ", " & 'Profit & Loss'!B20 & CHAR(10) & "Time: " & TEXT('Profit & Loss'!C20, "hh:mm AM/PM") & " - " & TEXT('Profit & Loss'!D20, "hh:mm AM/PM") & CHAR(10) & "Venue: " & 'Profit & Loss'!E20 & CHAR(10) & "Level: HB - LI" & CHAR(10) & "Cost: $" & 'Profit & Loss'!O20 & " per pax" & CHAR(10) & "Max " & 'Profit & Loss'!I20*6 & " pax," & " (" & 'Profit & Loss'!I20 & " courts)" & CHAR(10) & CHAR(10) & "RSL Ultimate shuttles provided" & CHAR(10) & CHAR(10) & "PM if interested, thank you!"," ") | B17: =IF('Profit & Loss'!A20>=TODAY(), "Date: " & TEXT('Profit & Loss'!A20,"dd mmm yyy") & ", " & 'Profit & Loss'!B20 & CHAR(10) & "Time: " & TEXT('Profit & Loss'!C20, "hh:mm AM/PM") & " - " & TEXT('Profit & Loss'!D20, "hh:mm AM/PM") & CHAR(10) & "Venue: " & 'Profit & Loss'!E20 & CHAR(10) & "Court No.: " & 'Profit & Loss'!F20 & CHAR(10) & "Level: HB - LI" & CHAR(10) & "Please transfer $" & 'Profit & Loss'!O20 & " per pax to Belle (83396501)" & CHAR(10) & CHAR(10) & IF('Profit & Loss'!I20=1, "1." & CHAR(10) & "2." & CHAR(10) & "3." & CHAR(10) & "4." & CHAR(10) & "5." & CHAR(10) & "6." & CHAR(10), IF('Profit & Loss'!I20=2, "1." & CHAR(10) & "2." & CHAR(10) & "3." & CHAR(10) & "4." & CHAR(10) & "5." & CHAR(10) & "6." & CHAR(10) & "7." & CHAR(10) & "8." & CHAR(10) & "9." & CHAR(10) & "10." & CHAR(10) & "11." & CHAR(10) & "12." & CHAR(10), IF('Profit & Loss'!I20=3, "1." & CHAR(10) & "2." & CHAR(10) & "3." & CHAR(10) & "4." & CHAR(10) & "5." & CHAR(10) & "6." & CHAR(10) & "7." & CHAR(10) & "8." & CHAR(10) & "9." & CHAR(10) & "10." & CHAR(10) & "11." & CHAR(10) & "12." & CHAR(10) & "13." & CHAR(10) & "14." & CHAR(10) & "15." & CHAR(10) & "16." & CHAR(10) & "17." & CHAR(10) & "18." & CHAR(10), " ")))," ")
A18: =IF('Profit & Loss'!A21>=TODAY(),"Looking for friendly players to join the following game: " & CHAR(10) & CHAR(10) & "Date: " & TEXT('Profit & Loss'!A21,"dd mmm yyy") & ", " & 'Profit & Loss'!B21 & CHAR(10) & "Time: " & TEXT('Profit & Loss'!C21, "hh:mm AM/PM") & " - " & TEXT('Profit & Loss'!D21, "hh:mm AM/PM") & CHAR(10) & "Venue: " & 'Profit & Loss'!E21 & CHAR(10) & "Level: HB - LI" & CHAR(10) & "Cost: $" & 'Profit & Loss'!O21 & " per pax" & CHAR(10) & "Max " & 'Profit & Loss'!I21*6 & " pax," & " (" & 'Profit & Loss'!I21 & " courts)" & CHAR(10) & CHAR(10) & "RSL Ultimate shuttles provided" & CHAR(10) & CHAR(10) & "PM if interested, thank you!"," ") | B18: =IF('Profit & Loss'!A21>=TODAY(), "Date: " & TEXT('Profit & Loss'!A21,"dd mmm yyy") & ", " & 'Profit & Loss'!B21 & CHAR(10) & "Time: " & TEXT('Profit & Loss'!C21, "hh:mm AM/PM") & " - " & TEXT('Profit & Loss'!D21, "hh:mm AM/PM") & CHAR(10) & "Venue: " & 'Profit & Loss'!E21 & CHAR(10) & "Court No.: " & 'Profit & Loss'!F21 & CHAR(10) & "Level: HB - LI" & CHAR(10) & "Please transfer $" & 'Profit & Loss'!O21 & " per pax to Belle (83396501)" & CHAR(10) & CHAR(10) & IF('Profit & Loss'!I21=1, "1." & CHAR(10) & "2." & CHAR(10) & "3." & CHAR(10) & "4." & CHAR(10) & "5." & CHAR(10) & "6." & CHAR(10), IF('Profit & Loss'!I21=2, "1." & CHAR(10) & "2." & CHAR(10) & "3." & CHAR(10) & "4." & CHAR(10) & "5." & CHAR(10) & "6." & CHAR(10) & "7." & CHAR(10) & "8." & CHAR(10) & "9." & CHAR(10) & "10." & CHAR(10) & "11." & CHAR(10) & "12." & CHAR(10), IF('Profit & Loss'!I21=3, "1." & CHAR(10) & "2." & CHAR(10) & "3." & CHAR(10) & "4." & CHAR(10) & "5." & CHAR(10) & "6." & CHAR(10) & "7." & CHAR(10) & "8." & CHAR(10) & "9." & CHAR(10) & "10." & CHAR(10) & "11." & CHAR(10) & "12." & CHAR(10) & "13." & CHAR(10) & "14." & CHAR(10) & "15." & CHAR(10) & "16." & CHAR(10) & "17." & CHAR(10) & "18." & CHAR(10), " ")))," ")
A19: =IF('Profit & Loss'!A22>=TODAY(),"Looking for friendly players to join the following game: " & CHAR(10) & CHAR(10) & "Date: " & TEXT('Profit & Loss'!A22,"dd mmm yyy") & ", " & 'Profit & Loss'!B22 & CHAR(10) & "Time: " & TEXT('Profit & Loss'!C22, "hh:mm AM/PM") & " - " & TEXT('Profit & Loss'!D22, "hh:mm AM/PM") & CHAR(10) & "Venue: " & 'Profit & Loss'!E22 & CHAR(10) & "Level: HB - LI" & CHAR(10) & "Cost: $" & 'Profit & Loss'!O22 & " per pax" & CHAR(10) & "Max " & 'Profit & Loss'!I22*6 & " pax," & " (" & 'Profit & Loss'!I22 & " courts)" & CHAR(10) & CHAR(10) & "RSL Ultimate shuttles provided" & CHAR(10) & CHAR(10) & "PM if interested, thank you!"," ") | B19: =IF('Profit & Loss'!A22>=TODAY(), "Date: " & TEXT('Profit & Loss'!A22,"dd mmm yyy") & ", " & 'Profit & Loss'!B22 & CHAR(10) & "Time: " & TEXT('Profit & Loss'!C22, "hh:mm AM/PM") & " - " & TEXT('Profit & Loss'!D22, "hh:mm AM/PM") & CHAR(10) & "Venue: " & 'Profit & Loss'!E22 & CHAR(10) & "Court No.: " & 'Profit & Loss'!F22 & CHAR(10) & "Level: HB - LI" & CHAR(10) & "Please transfer $" & 'Profit & Loss'!O22 & " per pax to Belle (83396501)" & CHAR(10) & CHAR(10) & IF('Profit & Loss'!I22=1, "1." & CHAR(10) & "2." & CHAR(10) & "3." & CHAR(10) & "4." & CHAR(10) & "5." & CHAR(10) & "6." & CHAR(10), IF('Profit & Loss'!I22=2, "1." & CHAR(10) & "2." & CHAR(10) & "3." & CHAR(10) & "4." & CHAR(10) & "5." & CHAR(10) & "6." & CHAR(10) & "7." & CHAR(10) & "8." & CHAR(10) & "9." & CHAR(10) & "10." & CHAR(10) & "11." & CHAR(10) & "12." & CHAR(10), IF('Profit & Loss'!I22=3, "1." & CHAR(10) & "2." & CHAR(10) & "3." & CHAR(10) & "4." & CHAR(10) & "5." & CHAR(10) & "6." & CHAR(10) & "7." & CHAR(10) & "8." & CHAR(10) & "9." & CHAR(10) & "10." & CHAR(10) & "11." & CHAR(10) & "12." & CHAR(10) & "13." & CHAR(10) & "14." & CHAR(10) & "15." & CHAR(10) & "16." & CHAR(10) & "17." & CHAR(10) & "18." & CHAR(10), " ")))," ")
A20: =IF('Profit & Loss'!A23>=TODAY(),"Looking for friendly players to join the following game: " & CHAR(10) & CHAR(10) & "Date: " & TEXT('Profit & Loss'!A23,"dd mmm yyy") & ", " & 'Profit & Loss'!B23 & CHAR(10) & "Time: " & TEXT('Profit & Loss'!C23, "hh:mm AM/PM") & " - " & TEXT('Profit & Loss'!D23, "hh:mm AM/PM") & CHAR(10) & "Venue: " & 'Profit & Loss'!E23 & CHAR(10) & "Level: HB - LI" & CHAR(10) & "Cost: $" & 'Profit & Loss'!O23 & " per pax" & CHAR(10) & "Max " & 'Profit & Loss'!I23*6 & " pax," & " (" & 'Profit & Loss'!I23 & " courts)" & CHAR(10) & CHAR(10) & "RSL Ultimate shuttles provided" & CHAR(10) & CHAR(10) & "PM if interested, thank you!"," ") | B20: =IF('Profit & Loss'!A23>=TODAY(), "Date: " & TEXT('Profit & Loss'!A23,"dd mmm yyy") & ", " & 'Profit & Loss'!B23 & CHAR(10) & "Time: " & TEXT('Profit & Loss'!C23, "hh:mm AM/PM") & " - " & TEXT('Profit & Loss'!D23, "hh:mm AM/PM") & CHAR(10) & "Venue: " & 'Profit & Loss'!E23 & CHAR(10) & "Court No.: " & 'Profit & Loss'!F23 & CHAR(10) & "Level: HB - LI" & CHAR(10) & "Please transfer $" & 'Profit & Loss'!O23 & " per pax to Belle (83396501)" & CHAR(10) & CHAR(10) & IF('Profit & Loss'!I23=1, "1." & CHAR(10) & "2." & CHAR(10) & "3." & CHAR(10) & "4." & CHAR(10) & "5." & CHAR(10) & "6." & CHAR(10), IF('Profit & Loss'!I23=2, "1." & CHAR(10) & "2." & CHAR(10) & "3." & CHAR(10) & "4." & CHAR(10) & "5." & CHAR(10) & "6." & CHAR(10) & "7." & CHAR(10) & "8." & CHAR(10) & "9." & CHAR(10) & "10." & CHAR(10) & "11." & CHAR(10) & "12." & CHAR(10), IF('Profit & Loss'!I23=3, "1." & CHAR(10) & "2." & CHAR(10) & "3." & CHAR(10) & "4." & CHAR(10) & "5." & CHAR(10) & "6." & CHAR(10) & "7." & CHAR(10) & "8." & CHAR(10) & "9." & CHAR(10) & "10." & CHAR(10) & "11." & CHAR(10) & "12." & CHAR(10) & "13." & CHAR(10) & "14." & CHAR(10) & "15." & CHAR(10) & "16." & CHAR(10) & "17." & CHAR(10) & "18." & CHAR(10), " ")))," ")
A21: =IF('Profit & Loss'!A24>=TODAY(),"Looking for friendly players to join the following game: " & CHAR(10) & CHAR(10) & "Date: " & TEXT('Profit & Loss'!A24,"dd mmm yyy") & ", " & 'Profit & Loss'!B24 & CHAR(10) & "Time: " & TEXT('Profit & Loss'!C24, "hh:mm AM/PM") & " - " & TEXT('Profit & Loss'!D24, "hh:mm AM/PM") & CHAR(10) & "Venue: " & 'Profit & Loss'!E24 & CHAR(10) & "Level: HB - LI" & CHAR(10) & "Cost: $" & 'Profit & Loss'!O24 & " per pax" & CHAR(10) & "Max " & 'Profit & Loss'!I24*6 & " pax," & " (" & 'Profit & Loss'!I24 & " courts)" & CHAR(10) & CHAR(10) & "RSL Ultimate shuttles provided" & CHAR(10) & CHAR(10) & "PM if interested, thank you!"," ") | B21: =IF('Profit & Loss'!A24>=TODAY(), "Date: " & TEXT('Profit & Loss'!A24,"dd mmm yyy") & ", " & 'Profit & Loss'!B24 & CHAR(10) & "Time: " & TEXT('Profit & Loss'!C24, "hh:mm AM/PM") & " - " & TEXT('Profit & Loss'!D24, "hh:mm AM/PM") & CHAR(10) & "Venue: " & 'Profit & Loss'!E24 & CHAR(10) & "Court No.: " & 'Profit & Loss'!F24 & CHAR(10) & "Level: HB - LI" & CHAR(10) & "Please transfer $" & 'Profit & Loss'!O24 & " per pax to Belle (83396501)" & CHAR(10) & CHAR(10) & IF('Profit & Loss'!I24=1, "1." & CHAR(10) & "2." & CHAR(10) & "3." & CHAR(10) & "4." & CHAR(10) & "5." & CHAR(10) & "6." & CHAR(10), IF('Profit & Loss'!I24=2, "1." & CHAR(10) & "2." & CHAR(10) & "3." & CHAR(10) & "4." & CHAR(10) & "5." & CHAR(10) & "6." & CHAR(10) & "7." & CHAR(10) & "8." & CHAR(10) & "9." & CHAR(10) & "10." & CHAR(10) & "11." & CHAR(10) & "12." & CHAR(10), IF('Profit & Loss'!I24=3, "1." & CHAR(10) & "2." & CHAR(10) & "3." & CHAR(10) & "4." & CHAR(10) & "5." & CHAR(10) & "6." & CHAR(10) & "7." & CHAR(10) & "8." & CHAR(10) & "9." & CHAR(10) & "10." & CHAR(10) & "11." & CHAR(10) & "12." & CHAR(10) & "13." & CHAR(10) & "14." & CHAR(10) & "15." & CHAR(10) & "16." & CHAR(10) & "17." & CHAR(10) & "18." & CHAR(10), " ")))," ")
A22: =IF('Profit & Loss'!A25>=TODAY(),"Looking for friendly players to join the following game: " & CHAR(10) & CHAR(10) & "Date: " & TEXT('Profit & Loss'!A25,"dd mmm yyy") & ", " & 'Profit & Loss'!B25 & CHAR(10) & "Time: " & TEXT('Profit & Loss'!C25, "hh:mm AM/PM") & " - " & TEXT('Profit & Loss'!D25, "hh:mm AM/PM") & CHAR(10) & "Venue: " & 'Profit & Loss'!E25 & CHAR(10) & "Level: HB - LI" & CHAR(10) & "Cost: $" & 'Profit & Loss'!O25 & " per pax" & CHAR(10) & "Max " & 'Profit & Loss'!I25*6 & " pax," & " (" & 'Profit & Loss'!I25 & " courts)" & CHAR(10) & CHAR(10) & "RSL Ultimate shuttles provided" & CHAR(10) & CHAR(10) & "PM if interested, thank you!"," ") | B22: =IF('Profit & Loss'!A25>=TODAY(), "Date: " & TEXT('Profit & Loss'!A25,"dd mmm yyy") & ", " & 'Profit & Loss'!B25 & CHAR(10) & "Time: " & TEXT('Profit & Loss'!C25, "hh:mm AM/PM") & " - " & TEXT('Profit & Loss'!D25, "hh:mm AM/PM") & CHAR(10) & "Venue: " & 'Profit & Loss'!E25 & CHAR(10) & "Court No.: " & 'Profit & Loss'!F25 & CHAR(10) & "Level: HB - LI" & CHAR(10) & "Please transfer $" & 'Profit & Loss'!O25 & " per pax to Belle (83396501)" & CHAR(10) & CHAR(10) & IF('Profit & Loss'!I25=1, "1." & CHAR(10) & "2." & CHAR(10) & "3." & CHAR(10) & "4." & CHAR(10) & "5." & CHAR(10) & "6." & CHAR(10), IF('Profit & Loss'!I25=2, "1." & CHAR(10) & "2." & CHAR(10) & "3." & CHAR(10) & "4." & CHAR(10) & "5." & CHAR(10) & "6." & CHAR(10) & "7." & CHAR(10) & "8." & CHAR(10) & "9." & CHAR(10) & "10." & CHAR(10) & "11." & CHAR(10) & "12." & CHAR(10), IF('Profit & Loss'!I25=3, "1." & CHAR(10) & "2." & CHAR(10) & "3." & CHAR(10) & "4." & CHAR(10) & "5." & CHAR(10) & "6." & CHAR(10) & "7." & CHAR(10) & "8." & CHAR(10) & "9." & CHAR(10) & "10." & CHAR(10) & "11." & CHAR(10) & "12." & CHAR(10) & "13." & CHAR(10) & "14." & CHAR(10) & "15." & CHAR(10) & "16." & CHAR(10) & "17." & CHAR(10) & "18." & CHAR(10), " ")))," ")
A23: =IF('Profit & Loss'!A26>=TODAY(),"Looking for friendly players to join the following game: " & CHAR(10) & CHAR(10) & "Date: " & TEXT('Profit & Loss'!A26,"dd mmm yyy") & ", " & 'Profit & Loss'!B26 & CHAR(10) & "Time: " & TEXT('Profit & Loss'!C26, "hh:mm AM/PM") & " - " & TEXT('Profit & Loss'!D26, "hh:mm AM/PM") & CHAR(10) & "Venue: " & 'Profit & Loss'!E26 & CHAR(10) & "Level: HB - LI" & CHAR(10) & "Cost: $" & 'Profit & Loss'!O26 & " per pax" & CHAR(10) & "Max " & 'Profit & Loss'!I26*6 & " pax," & " (" & 'Profit & Loss'!I26 & " courts)" & CHAR(10) & CHAR(10) & "RSL Ultimate shuttles provided" & CHAR(10) & CHAR(10) & "PM if interested, thank you!"," ") | B23: =IF('Profit & Loss'!A26>=TODAY(), "Date: " & TEXT('Profit & Loss'!A26,"dd mmm yyy") & ", " & 'Profit & Loss'!B26 & CHAR(10) & "Time: " & TEXT('Profit & Loss'!C26, "hh:mm AM/PM") & " - " & TEXT('Profit & Loss'!D26, "hh:mm AM/PM") & CHAR(10) & "Venue: " & 'Profit & Loss'!E26 & CHAR(10) & "Court No.: " & 'Profit & Loss'!F26 & CHAR(10) & "Level: HB - LI" & CHAR(10) & "Please transfer $" & 'Profit & Loss'!O26 & " per pax to Belle (83396501)" & CHAR(10) & CHAR(10) & IF('Profit & Loss'!I26=1, "1." & CHAR(10) & "2." & CHAR(10) & "3." & CHAR(10) & "4." & CHAR(10) & "5." & CHAR(10) & "6." & CHAR(10), IF('Profit & Loss'!I26=2, "1." & CHAR(10) & "2." & CHAR(10) & "3." & CHAR(10) & "4." & CHAR(10) & "5." & CHAR(10) & "6." & CHAR(10) & "7." & CHAR(10) & "8." & CHAR(10) & "9." & CHAR(10) & "10." & CHAR(10) & "11." & CHAR(10) & "12." & CHAR(10), IF('Profit & Loss'!I26=3, "1." & CHAR(10) & "2." & CHAR(10) & "3." & CHAR(10) & "4." & CHAR(10) & "5." & CHAR(10) & "6." & CHAR(10) & "7." & CHAR(10) & "8." & CHAR(10) & "9." & CHAR(10) & "10." & CHAR(10) & "11." & CHAR(10) & "12." & CHAR(10) & "13." & CHAR(10) & "14." & CHAR(10) & "15." & CHAR(10) & "16." & CHAR(10) & "17." & CHAR(10) & "18." & CHAR(10), " ")))," ")
A24: =IF('Profit & Loss'!A27>=TODAY(),"Looking for friendly players to join the following game: " & CHAR(10) & CHAR(10) & "Date: " & TEXT('Profit & Loss'!A27,"dd mmm yyy") & ", " & 'Profit & Loss'!B27 & CHAR(10) & "Time: " & TEXT('Profit & Loss'!C27, "hh:mm AM/PM") & " - " & TEXT('Profit & Loss'!D27, "hh:mm AM/PM") & CHAR(10) & "Venue: " & 'Profit & Loss'!E27 & CHAR(10) & "Level: HB - LI" & CHAR(10) & "Cost: $" & 'Profit & Loss'!O27 & " per pax" & CHAR(10) & "Max " & 'Profit & Loss'!I27*6 & " pax," & " (" & 'Profit & Loss'!I27 & " courts)" & CHAR(10) & CHAR(10) & "RSL Ultimate shuttles provided" & CHAR(10) & CHAR(10) & "PM if interested, thank you!"," ") | B24: =IF('Profit & Loss'!A27>=TODAY(), "Date: " & TEXT('Profit & Loss'!A27,"dd mmm yyy") & ", " & 'Profit & Loss'!B27 & CHAR(10) & "Time: " & TEXT('Profit & Loss'!C27, "hh:mm AM/PM") & " - " & TEXT('Profit & Loss'!D27, "hh:mm AM/PM") & CHAR(10) & "Venue: " & 'Profit & Loss'!E27 & CHAR(10) & "Court No.: " & 'Profit & Loss'!F27 & CHAR(10) & "Level: HB - LI" & CHAR(10) & "Please transfer $" & 'Profit & Loss'!O27 & " per pax to Belle (83396501)" & CHAR(10) & CHAR(10) & IF('Profit & Loss'!I27=1, "1." & CHAR(10) & "2." & CHAR(10) & "3." & CHAR(10) & "4." & CHAR(10) & "5." & CHAR(10) & "6." & CHAR(10), IF('Profit & Loss'!I27=2, "1." & CHAR(10) & "2." & CHAR(10) & "3." & CHAR(10) & "4." & CHAR(10) & "5." & CHAR(10) & "6." & CHAR(10) & "7." & CHAR(10) & "8." & CHAR(10) & "9." & CHAR(10) & "10." & CHAR(10) & "11." & CHAR(10) & "12." & CHAR(10), IF('Profit & Loss'!I27=3, "1." & CHAR(10) & "2." & CHAR(10) & "3." & CHAR(10) & "4." & CHAR(10) & "5." & CHAR(10) & "6." & CHAR(10) & "7." & CHAR(10) & "8." & CHAR(10) & "9." & CHAR(10) & "10." & CHAR(10) & "11." & CHAR(10) & "12." & CHAR(10) & "13." & CHAR(10) & "14." & CHAR(10) & "15." & CHAR(10) & "16." & CHAR(10) & "17." & CHAR(10) & "18." & CHAR(10), " ")))," ")
A25: =IF('Profit & Loss'!A28>=TODAY(),"Looking for friendly players to join the following game: " & CHAR(10) & CHAR(10) & "Date: " & TEXT('Profit & Loss'!A28,"dd mmm yyy") & ", " & 'Profit & Loss'!B28 & CHAR(10) & "Time: " & TEXT('Profit & Loss'!C28, "hh:mm AM/PM") & " - " & TEXT('Profit & Loss'!D28, "hh:mm AM/PM") & CHAR(10) & "Venue: " & 'Profit & Loss'!E28 & CHAR(10) & "Level: HB - LI" & CHAR(10) & "Cost: $" & 'Profit & Loss'!O28 & " per pax" & CHAR(10) & "Max " & 'Profit & Loss'!I28*6 & " pax," & " (" & 'Profit & Loss'!I28 & " courts)" & CHAR(10) & CHAR(10) & "RSL Ultimate shuttles provided" & CHAR(10) & CHAR(10) & "PM if interested, thank you!"," ") | B25: =IF('Profit & Loss'!A28>=TODAY(), "Date: " & TEXT('Profit & Loss'!A28,"dd mmm yyy") & ", " & 'Profit & Loss'!B28 & CHAR(10) & "Time: " & TEXT('Profit & Loss'!C28, "hh:mm AM/PM") & " - " & TEXT('Profit & Loss'!D28, "hh:mm AM/PM") & CHAR(10) & "Venue: " & 'Profit & Loss'!E28 & CHAR(10) & "Court No.: " & 'Profit & Loss'!F28 & CHAR(10) & "Level: HB - LI" & CHAR(10) & "Please transfer $" & 'Profit & Loss'!O28 & " per pax to Belle (83396501)" & CHAR(10) & CHAR(10) & IF('Profit & Loss'!I28=1, "1." & CHAR(10) & "2." & CHAR(10) & "3." & CHAR(10) & "4." & CHAR(10) & "5." & CHAR(10) & "6." & CHAR(10), IF('Profit & Loss'!I28=2, "1." & CHAR(10) & "2." & CHAR(10) & "3." & CHAR(10) & "4." & CHAR(10) & "5." & CHAR(10) & "6." & CHAR(10) & "7." & CHAR(10) & "8." & CHAR(10) & "9." & CHAR(10) & "10." & CHAR(10) & "11." & CHAR(10) & "12." & CHAR(10), IF('Profit & Loss'!I28=3, "1." & CHAR(10) & "2." & CHAR(10) & "3." & CHAR(10) & "4." & CHAR(10) & "5." & CHAR(10) & "6." & CHAR(10) & "7." & CHAR(10) & "8." & CHAR(10) & "9." & CHAR(10) & "10." & CHAR(10) & "11." & CHAR(10) & "12." & CHAR(10) & "13." & CHAR(10) & "14." & CHAR(10) & "15." & CHAR(10) & "16." & CHAR(10) & "17." & CHAR(10) & "18." & CHAR(10), " ")))," ")
A26: =IF('Profit & Loss'!A29>=TODAY(),"Looking for friendly players to join the following game: " & CHAR(10) & CHAR(10) & "Date: " & TEXT('Profit & Loss'!A29,"dd mmm yyy") & ", " & 'Profit & Loss'!B29 & CHAR(10) & "Time: " & TEXT('Profit & Loss'!C29, "hh:mm AM/PM") & " - " & TEXT('Profit & Loss'!D29, "hh:mm AM/PM") & CHAR(10) & "Venue: " & 'Profit & Loss'!E29 & CHAR(10) & "Level: HB - LI" & CHAR(10) & "Cost: $" & 'Profit & Loss'!O29 & " per pax" & CHAR(10) & "Max " & 'Profit & Loss'!I29*6 & " pax," & " (" & 'Profit & Loss'!I29 & " courts)" & CHAR(10) & CHAR(10) & "RSL Ultimate shuttles provided" & CHAR(10) & CHAR(10) & "PM if interested, thank you!"," ") | B26: =IF('Profit & Loss'!A29>=TODAY(), "Date: " & TEXT('Profit & Loss'!A29,"dd mmm yyy") & ", " & 'Profit & Loss'!B29 & CHAR(10) & "Time: " & TEXT('Profit & Loss'!C29, "hh:mm AM/PM") & " - " & TEXT('Profit & Loss'!D29, "hh:mm AM/PM") & CHAR(10) & "Venue: " & 'Profit & Loss'!E29 & CHAR(10) & "Court No.: " & 'Profit & Loss'!F29 & CHAR(10) & "Level: HB - LI" & CHAR(10) & "Please transfer $" & 'Profit & Loss'!O29 & " per pax to Belle (83396501)" & CHAR(10) & CHAR(10) & IF('Profit & Loss'!I29=1, "1." & CHAR(10) & "2." & CHAR(10) & "3." & CHAR(10) & "4." & CHAR(10) & "5." & CHAR(10) & "6." & CHAR(10), IF('Profit & Loss'!I29=2, "1." & CHAR(10) & "2." & CHAR(10) & "3." & CHAR(10) & "4." & CHAR(10) & "5." & CHAR(10) & "6." & CHAR(10) & "7." & CHAR(10) & "8." & CHAR(10) & "9." & CHAR(10) & "10." & CHAR(10) & "11." & CHAR(10) & "12." & CHAR(10), IF('Profit & Loss'!I29=3, "1." & CHAR(10) & "2." & CHAR(10) & "3." & CHAR(10) & "4." & CHAR(10) & "5." & CHAR(10) & "6." & CHAR(10) & "7." & CHAR(10) & "8." & CHAR(10) & "9." & CHAR(10) & "10." & CHAR(10) & "11." & CHAR(10) & "12." & CHAR(10) & "13." & CHAR(10) & "14." & CHAR(10) & "15." & CHAR(10) & "16." & CHAR(10) & "17." & CHAR(10) & "18." & CHAR(10), " ")))," ")
A27: =IF('Profit & Loss'!A30>=TODAY(),"Looking for friendly players to join the following game: " & CHAR(10) & CHAR(10) & "Date: " & TEXT('Profit & Loss'!A30,"dd mmm yyy") & ", " & 'Profit & Loss'!B30 & CHAR(10) & "Time: " & TEXT('Profit & Loss'!C30, "hh:mm AM/PM") & " - " & TEXT('Profit & Loss'!D30, "hh:mm AM/PM") & CHAR(10) & "Venue: " & 'Profit & Loss'!E30 & CHAR(10) & "Level: HB - LI" & CHAR(10) & "Cost: $" & 'Profit & Loss'!O30 & " per pax" & CHAR(10) & "Max " & 'Profit & Loss'!I30*6 & " pax," & " (" & 'Profit & Loss'!I30 & " courts)" & CHAR(10) & CHAR(10) & "RSL Ultimate shuttles provided" & CHAR(10) & CHAR(10) & "PM if interested, thank you!"," ") | B27: =IF('Profit & Loss'!A30>=TODAY(), "Date: " & TEXT('Profit & Loss'!A30,"dd mmm yyy") & ", " & 'Profit & Loss'!B30 & CHAR(10) & "Time: " & TEXT('Profit & Loss'!C30, "hh:mm AM/PM") & " - " & TEXT('Profit & Loss'!D30, "hh:mm AM/PM") & CHAR(10) & "Venue: " & 'Profit & Loss'!E30 & CHAR(10) & "Court No.: " & 'Profit & Loss'!F30 & CHAR(10) & "Level: HB - LI" & CHAR(10) & "Please transfer $" & 'Profit & Loss'!O30 & " per pax to Belle (83396501)" & CHAR(10) & CHAR(10) & IF('Profit & Loss'!I30=1, "1." & CHAR(10) & "2." & CHAR(10) & "3." & CHAR(10) & "4." & CHAR(10) & "5." & CHAR(10) & "6." & CHAR(10), IF('Profit & Loss'!I30=2, "1." & CHAR(10) & "2." & CHAR(10) & "3." & CHAR(10) & "4." & CHAR(10) & "5." & CHAR(10) & "6." & CHAR(10) & "7." & CHAR(10) & "8." & CHAR(10) & "9." & CHAR(10) & "10." & CHAR(10) & "11." & CHAR(10) & "12." & CHAR(10), IF('Profit & Loss'!I30=3, "1." & CHAR(10) & "2." & CHAR(10) & "3." & CHAR(10) & "4." & CHAR(10) & "5." & CHAR(10) & "6." & CHAR(10) & "7." & CHAR(10) & "8." & CHAR(10) & "9." & CHAR(10) & "10." & CHAR(10) & "11." & CHAR(10) & "12." & CHAR(10) & "13." & CHAR(10) & "14." & CHAR(10) & "15." & CHAR(10) & "16." & CHAR(10) & "17." & CHAR(10) & "18." & CHAR(10), " ")))," ")
A28: =IF('Profit & Loss'!A31>=TODAY(),"Looking for friendly players to join the following game: " & CHAR(10) & CHAR(10) & "Date: " & TEXT('Profit & Loss'!A31,"dd mmm yyy") & ", " & 'Profit & Loss'!B31 & CHAR(10) & "Time: " & TEXT('Profit & Loss'!C31, "hh:mm AM/PM") & " - " & TEXT('Profit & Loss'!D31, "hh:mm AM/PM") & CHAR(10) & "Venue: " & 'Profit & Loss'!E31 & CHAR(10) & "Level: HB - LI" & CHAR(10) & "Cost: $" & 'Profit & Loss'!O31 & " per pax" & CHAR(10) & "Max " & 'Profit & Loss'!I31*6 & " pax," & " (" & 'Profit & Loss'!I31 & " courts)" & CHAR(10) & CHAR(10) & "RSL Ultimate shuttles provided" & CHAR(10) & CHAR(10) & "PM if interested, thank you!"," ") | B28: =IF('Profit & Loss'!A31>=TODAY(), "Date: " & TEXT('Profit & Loss'!A31,"dd mmm yyy") & ", " & 'Profit & Loss'!B31 & CHAR(10) & "Time: " & TEXT('Profit & Loss'!C31, "hh:mm AM/PM") & " - " & TEXT('Profit & Loss'!D31, "hh:mm AM/PM") & CHAR(10) & "Venue: " & 'Profit & Loss'!E31 & CHAR(10) & "Court No.: " & 'Profit & Loss'!F31 & CHAR(10) & "Level: HB - LI" & CHAR(10) & "Please transfer $" & 'Profit & Loss'!O31 & " per pax to Belle (83396501)" & CHAR(10) & CHAR(10) & IF('Profit & Loss'!I31=1, "1." & CHAR(10) & "2." & CHAR(10) & "3." & CHAR(10) & "4." & CHAR(10) & "5." & CHAR(10) & "6." & CHAR(10), IF('Profit & Loss'!I31=2, "1." & CHAR(10) & "2." & CHAR(10) & "3." & CHAR(10) & "4." & CHAR(10) & "5." & CHAR(10) & "6." & CHAR(10) & "7." & CHAR(10) & "8." & CHAR(10) & "9." & CHAR(10) & "10." & CHAR(10) & "11." & CHAR(10) & "12." & CHAR(10), IF('Profit & Loss'!I31=3, "1." & CHAR(10) & "2." & CHAR(10) & "3." & CHAR(10) & "4." & CHAR(10) & "5." & CHAR(10) & "6." & CHAR(10) & "7." & CHAR(10) & "8." & CHAR(10) & "9." & CHAR(10) & "10." & CHAR(10) & "11." & CHAR(10) & "12." & CHAR(10) & "13." & CHAR(10) & "14." & CHAR(10) & "15." & CHAR(10) & "16." & CHAR(10) & "17." & CHAR(10) & "18." & CHAR(10), " ")))," ")
... A32: =IF('Profit & Loss'!A35>=TODAY(),"Looking for friendly players to join the following game: " & CHAR(10) & CHAR(10) & "Date: " & TEXT('Profit & Loss'!A35,"dd mmm yyy") & ", " & 'Profit & Loss'!B35 & CHAR(10) & "Time: " & TEXT('Profit & Loss'!C35, "hh:mm AM/PM") & " - " & TEXT('Profit & Loss'!D35, "hh:mm AM/PM") & CHAR(10) & "Venue: " & 'Profit & Loss'!E35 & CHAR(10) & "Level: HB - LI" & CHAR(10) & "Cost: $" & 'Profit & Loss'!O35 & " per pax" & CHAR(10) & "Max " & 'Profit & Loss'!I35*6 & " pax," & " (" & 'Profit & Loss'!I35 & " courts)" & CHAR(10) & CHAR(10) & "RSL Ultimate shuttles provided" & CHAR(10) & CHAR(10) & "PM if interested, thank you!"," ") | B32: =IF('Profit & Loss'!A35>=TODAY(), "Date: " & TEXT('Profit & Loss'!A35,"dd mmm yyy") & ", " & 'Profit & Loss'!B35 & CHAR(10) & "Time: " & TEXT('Profit & Loss'!C35, "hh:mm AM/PM") & " - " & TEXT('Profit & Loss'!D35, "hh:mm AM/PM") & CHAR(10) & "Venue: " & 'Profit & Loss'!E35 & CHAR(10) & "Court No.: " & 'Profit & Loss'!F35 & CHAR(10) & "Level: HB - LI" & CHAR(10) & "Please transfer $" & 'Profit & Loss'!O35 & " per pax to Belle (83396501)" & CHAR(10) & CHAR(10) & IF('Profit & Loss'!I35=1, "1." & CHAR(10) & "2." & CHAR(10) & "3." & CHAR(10) & "4." & CHAR(10) & "5." & CHAR(10) & "6." & CHAR(10), IF('Profit & Loss'!I35=2, "1." & CHAR(10) & "2." & CHAR(10) & "3." & CHAR(10) & "4." & CHAR(10) & "5." & CHAR(10) & "6." & CHAR(10) & "7." & CHAR(10) & "8." & CHAR(10) & "9." & CHAR(10) & "10." & CHAR(10) & "11." & CHAR(10) & "12." & CHAR(10), IF('Profit & Loss'!I35=3, "1." & CHAR(10) & "2." & CHAR(10) & "3." & CHAR(10) & "4." & CHAR(10) & "5." & CHAR(10) & "6." & CHAR(10) & "7." & CHAR(10) & "8." & CHAR(10) & "9." & CHAR(10) & "10." & CHAR(10) & "11." & CHAR(10) & "12." & CHAR(10) & "13." & CHAR(10) & "14." & CHAR(10) & "15." & CHAR(10) & "16." & CHAR(10) & "17." & CHAR(10) & "18." & CHAR(10), " ")))," ")
A33: =IF('Profit & Loss'!A37>=TODAY(),"Looking for friendly players to join the following game: " & CHAR(10) & CHAR(10) & "Date: " & TEXT('Profit & Loss'!A37,"dd mmm yyy") & ", " & 'Profit & Loss'!B37 & CHAR(10) & "Time: " & TEXT('Profit & Loss'!C37, "hh:mm AM/PM") & " - " & TEXT('Profit & Loss'!D37, "hh:mm AM/PM") & CHAR(10) & "Venue: " & 'Profit & Loss'!E37 & CHAR(10) & "Level: HB - LI" & CHAR(10) & "Cost: $" & 'Profit & Loss'!O37 & " per pax" & CHAR(10) & "Max " & 'Profit & Loss'!I37*6 & " pax," & " (" & 'Profit & Loss'!I37 & " courts)" & CHAR(10) & CHAR(10) & "RSL Ultimate shuttles provided" & CHAR(10) & CHAR(10) & "PM if interested, thank you!"," ") | B33: =IF('Profit & Loss'!A37>=TODAY(), "Date: " & TEXT('Profit & Loss'!A37,"dd mmm yyy") & ", " & 'Profit & Loss'!B37 & CHAR(10) & "Time: " & TEXT('Profit & Loss'!C37, "hh:mm AM/PM") & " - " & TEXT('Profit & Loss'!D37, "hh:mm AM/PM") & CHAR(10) & "Venue: " & 'Profit & Loss'!E37 & CHAR(10) & "Court No.: " & 'Profit & Loss'!F37 & CHAR(10) & "Level: HB - LI" & CHAR(10) & "Please transfer $" & 'Profit & Loss'!O37 & " per pax to Belle (83396501)" & CHAR(10) & CHAR(10) & IF('Profit & Loss'!I37=1, "1." & CHAR(10) & "2." & CHAR(10) & "3." & CHAR(10) & "4." & CHAR(10) & "5." & CHAR(10) & "6." & CHAR(10), IF('Profit & Loss'!I37=2, "1." & CHAR(10) & "2." & CHAR(10) & "3." & CHAR(10) & "4." & CHAR(10) & "5." & CHAR(10) & "6." & CHAR(10) & "7." & CHAR(10) & "8." & CHAR(10) & "9." & CHAR(10) & "10." & CHAR(10) & "11." & CHAR(10) & "12." & CHAR(10), IF('Profit & Loss'!I37=3, "1." & CHAR(10) & "2." & CHAR(10) & "3." & CHAR(10) & "4." & CHAR(10) & "5." & CHAR(10) & "6." & CHAR(10) & "7." & CHAR(10) & "8." & CHAR(10) & "9." & CHAR(10) & "10." & CHAR(10) & "11." & CHAR(10) & "12." & CHAR(10) & "13." & CHAR(10) & "14." & CHAR(10) & "15." & CHAR(10) & "16." & CHAR(10) & "17." & CHAR(10) & "18." & CHAR(10), " ")))," ")
A34: =IF('Profit & Loss'!A36>=TODAY(),"Looking for friendly players to join the following game: " & CHAR(10) & CHAR(10) & "Date: " & TEXT('Profit & Loss'!A36,"dd mmm yyy") & ", " & 'Profit & Loss'!B36 & CHAR(10) & "Time: " & TEXT('Profit & Loss'!C36, "hh:mm AM/PM") & " - " & TEXT('Profit & Loss'!D36, "hh:mm AM/PM") & CHAR(10) & "Venue: " & 'Profit & Loss'!E36 & CHAR(10) & "Level: HB - LI" & CHAR(10) & "Cost: $" & 'Profit & Loss'!O36 & " per pax" & CHAR(10) & "Max " & 'Profit & Loss'!I36*6 & " pax," & " (" & 'Profit & Loss'!I36 & " courts)" & CHAR(10) & CHAR(10) & "RSL Ultimate shuttles provided" & CHAR(10) & CHAR(10) & "PM if interested, thank you!"," ") | B34: =IF('Profit & Loss'!A36>=TODAY(), "Date: " & TEXT('Profit & Loss'!A36,"dd mmm yyy") & ", " & 'Profit & Loss'!B36 & CHAR(10) & "Time: " & TEXT('Profit & Loss'!C36, "hh:mm AM/PM") & " - " & TEXT('Profit & Loss'!D36, "hh:mm AM/PM") & CHAR(10) & "Venue: " & 'Profit & Loss'!E36 & CHAR(10) & "Court No.: " & 'Profit & Loss'!F36 & CHAR(10) & "Level: HB - LI" & CHAR(10) & "Please transfer $" & 'Profit & Loss'!O36 & " per pax to Belle (83396501)" & CHAR(10) & CHAR(10) & IF('Profit & Loss'!I36=1, "1." & CHAR(10) & "2." & CHAR(10) & "3." & CHAR(10) & "4." & CHAR(10) & "5." & CHAR(10) & "6." & CHAR(10), IF('Profit & Loss'!I36=2, "1." & CHAR(10) & "2." & CHAR(10) & "3." & CHAR(10) & "4." & CHAR(10) & "5." & CHAR(10) & "6." & CHAR(10) & "7." & CHAR(10) & "8." & CHAR(10) & "9." & CHAR(10) & "10." & CHAR(10) & "11." & CHAR(10) & "12." & CHAR(10), IF('Profit & Loss'!I36=3, "1." & CHAR(10) & "2." & CHAR(10) & "3." & CHAR(10) & "4." & CHAR(10) & "5." & CHAR(10) & "6." & CHAR(10) & "7." & CHAR(10) & "8." & CHAR(10) & "9." & CHAR(10) & "10." & CHAR(10) & "11." & CHAR(10) & "12." & CHAR(10) & "13." & CHAR(10) & "14." & CHAR(10) & "15." & CHAR(10) & "16." & CHAR(10) & "17." & CHAR(10) & "18." & CHAR(10), " ")))," ")
A35: =IF('Profit & Loss'!A38>=TODAY(),"Looking for friendly players to join the following game: " & CHAR(10) & CHAR(10) & "Date: " & TEXT('Profit & Loss'!A38,"dd mmm yyy") & ", " & 'Profit & Loss'!B38 & CHAR(10) & "Time: " & TEXT('Profit & Loss'!C38, "hh:mm AM/PM") & " - " & TEXT('Profit & Loss'!D38, "hh:mm AM/PM") & CHAR(10) & "Venue: " & 'Profit & Loss'!E38 & CHAR(10) & "Level: HB - LI" & CHAR(10) & "Cost: $" & 'Profit & Loss'!O38 & " per pax" & CHAR(10) & "Max " & 'Profit & Loss'!I38*6 & " pax," & " (" & 'Profit & Loss'!I38 & " courts)" & CHAR(10) & CHAR(10) & "RSL Ultimate shuttles provided" & CHAR(10) & CHAR(10) & "PM if interested, thank you!"," ") | B35: =IF('Profit & Loss'!A38>=TODAY(), "Date: " & TEXT('Profit & Loss'!A38,"dd mmm yyy") & ", " & 'Profit & Loss'!B38 & CHAR(10) & "Time: " & TEXT('Profit & Loss'!C38, "hh:mm AM/PM") & " - " & TEXT('Profit & Loss'!D38, "hh:mm AM/PM") & CHAR(10) & "Venue: " & 'Profit & Loss'!E38 & CHAR(10) & "Court No.: " & 'Profit & Loss'!F38 & CHAR(10) & "Level: HB - LI" & CHAR(10) & "Please transfer $" & 'Profit & Loss'!O38 & " per pax to Belle (83396501)" & CHAR(10) & CHAR(10) & IF('Profit & Loss'!I38=1, "1." & CHAR(10) & "2." & CHAR(10) & "3." & CHAR(10) & "4." & CHAR(10) & "5." & CHAR(10) & "6." & CHAR(10), IF('Profit & Loss'!I38=2, "1." & CHAR(10) & "2." & CHAR(10) & "3." & CHAR(10) & "4." & CHAR(10) & "5." & CHAR(10) & "6." & CHAR(10) & "7." & CHAR(10) & "8." & CHAR(10) & "9." & CHAR(10) & "10." & CHAR(10) & "11." & CHAR(10) & "12." & CHAR(10), IF('Profit & Loss'!I38=3, "1." & CHAR(10) & "2." & CHAR(10) & "3." & CHAR(10) & "4." & CHAR(10) & "5." & CHAR(10) & "6." & CHAR(10) & "7." & CHAR(10) & "8." & CHAR(10) & "9." & CHAR(10) & "10." & CHAR(10) & "11." & CHAR(10) & "12." & CHAR(10) & "13." & CHAR(10) & "14." & CHAR(10) & "15." & CHAR(10) & "16." & CHAR(10) & "17." & CHAR(10) & "18." & CHAR(10), " ")))," ")
A36: =IF('Profit & Loss'!A39>=TODAY(),"Looking for friendly players to join the following game: " & CHAR(10) & CHAR(10) & "Date: " & TEXT('Profit & Loss'!A39,"dd mmm yyy") & ", " & 'Profit & Loss'!B39 & CHAR(10) & "Time: " & TEXT('Profit & Loss'!C39, "hh:mm AM/PM") & " - " & TEXT('Profit & Loss'!D39, "hh:mm AM/PM") & CHAR(10) & "Venue: " & 'Profit & Loss'!E39 & CHAR(10) & "Level: HB - LI" & CHAR(10) & "Cost: $" & 'Profit & Loss'!O39 & " per pax" & CHAR(10) & "Max " & 'Profit & Loss'!I39*6 & " pax," & " (" & 'Profit & Loss'!I39 & " courts)" & CHAR(10) & CHAR(10) & "RSL Ultimate shuttles provided" & CHAR(10) & CHAR(10) & "PM if interested, thank you!"," ") | B36: =IF('Profit & Loss'!A39>=TODAY(), "Date: " & TEXT('Profit & Loss'!A39,"dd mmm yyy") & ", " & 'Profit & Loss'!B39 & CHAR(10) & "Time: " & TEXT('Profit & Loss'!C39, "hh:mm AM/PM") & " - " & TEXT('Profit & Loss'!D39, "hh:mm AM/PM") & CHAR(10) & "Venue: " & 'Profit & Loss'!E39 & CHAR(10) & "Court No.: " & 'Profit & Loss'!F39 & CHAR(10) & "Level: HB - LI" & CHAR(10) & "Please transfer $" & 'Profit & Loss'!O39 & " per pax to Belle (83396501)" & CHAR(10) & CHAR(10) & IF('Profit & Loss'!I39=1, "1." & CHAR(10) & "2." & CHAR(10) & "3." & CHAR(10) & "4." & CHAR(10) & "5." & CHAR(10) & "6." & CHAR(10), IF('Profit & Loss'!I39=2, "1." & CHAR(10) & "2." & CHAR(10) & "3." & CHAR(10) & "4." & CHAR(10) & "5." & CHAR(10) & "6." & CHAR(10) & "7." & CHAR(10) & "8." & CHAR(10) & "9." & CHAR(10) & "10." & CHAR(10) & "11." & CHAR(10) & "12." & CHAR(10), IF('Profit & Loss'!I39=3, "1." & CHAR(10) & "2." & CHAR(10) & "3." & CHAR(10) & "4." & CHAR(10) & "5." & CHAR(10) & "6." & CHAR(10) & "7." & CHAR(10) & "8." & CHAR(10) & "9." & CHAR(10) & "10." & CHAR(10) & "11." & CHAR(10) & "12." & CHAR(10) & "13." & CHAR(10) & "14." & CHAR(10) & "15." & CHAR(10) & "16." & CHAR(10) & "17." & CHAR(10) & "18." & CHAR(10), " ")))," ")
A37: =IF('Profit & Loss'!A40>=TODAY(),"Looking for friendly players to join the following game: " & CHAR(10) & CHAR(10) & "Date: " & TEXT('Profit & Loss'!A40,"dd mmm yyy") & ", " & 'Profit & Loss'!B40 & CHAR(10) & "Time: " & TEXT('Profit & Loss'!C40, "hh:mm AM/PM") & " - " & TEXT('Profit & Loss'!D40, "hh:mm AM/PM") & CHAR(10) & "Venue: " & 'Profit & Loss'!E40 & CHAR(10) & "Level: HB - LI" & CHAR(10) & "Cost: $" & 'Profit & Loss'!O40 & " per pax" & CHAR(10) & "Max " & 'Profit & Loss'!I40*6 & " pax," & " (" & 'Profit & Loss'!I40 & " courts)" & CHAR(10) & CHAR(10) & "RSL Ultimate shuttles provided" & CHAR(10) & CHAR(10) & "PM if interested, thank you!"," ") | B37: =IF('Profit & Loss'!A40>=TODAY(), "Date: " & TEXT('Profit & Loss'!A40,"dd mmm yyy") & ", " & 'Profit & Loss'!B40 & CHAR(10) & "Time: " & TEXT('Profit & Loss'!C40, "hh:mm AM/PM") & " - " & TEXT('Profit & Loss'!D40, "hh:mm AM/PM") & CHAR(10) & "Venue: " & 'Profit & Loss'!E40 & CHAR(10) & "Court No.: " & 'Profit & Loss'!F40 & CHAR(10) & "Level: HB - LI" & CHAR(10) & "Please transfer $" & 'Profit & Loss'!O40 & " per pax to Belle (83396501)" & CHAR(10) & CHAR(10) & IF('Profit & Loss'!I40=1, "1." & CHAR(10) & "2." & CHAR(10) & "3." & CHAR(10) & "4." & CHAR(10) & "5." & CHAR(10) & "6." & CHAR(10), IF('Profit & Loss'!I40=2, "1." & CHAR(10) & "2." & CHAR(10) & "3." & CHAR(10) & "4." & CHAR(10) & "5." & CHAR(10) & "6." & CHAR(10) & "7." & CHAR(10) & "8." & CHAR(10) & "9." & CHAR(10) & "10." & CHAR(10) & "11." & CHAR(10) & "12." & CHAR(10), IF('Profit & Loss'!I40=3, "1." & CHAR(10) & "2." & CHAR(10) & "3." & CHAR(10) & "4." & CHAR(10) & "5." & CHAR(10) & "6." & CHAR(10) & "7." & CHAR(10) & "8." & CHAR(10) & "9." & CHAR(10) & "10." & CHAR(10) & "11." & CHAR(10) & "12." & CHAR(10) & "13." & CHAR(10) & "14." & CHAR(10) & "15." & CHAR(10) & "16." & CHAR(10) & "17." & CHAR(10) & "18." & CHAR(10), " ")))," ")
A38: =IF('Profit & Loss'!A41>=TODAY(),"Looking for friendly players to join the following game: " & CHAR(10) & CHAR(10) & "Date: " & TEXT('Profit & Loss'!A41,"dd mmm yyy") & ", " & 'Profit & Loss'!B41 & CHAR(10) & "Time: " & TEXT('Profit & Loss'!C41, "hh:mm AM/PM") & " - " & TEXT('Profit & Loss'!D41, "hh:mm AM/PM") & CHAR(10) & "Venue: " & 'Profit & Loss'!E41 & CHAR(10) & "Level: HB - LI" & CHAR(10) & "Cost: $" & 'Profit & Loss'!O41 & " per pax" & CHAR(10) & "Max " & 'Profit & Loss'!I41*6 & " pax," & " (" & 'Profit & Loss'!I41 & " courts)" & CHAR(10) & CHAR(10) & "RSL Ultimate shuttles provided" & CHAR(10) & CHAR(10) & "PM if interested, thank you!"," ") | B38: =IF('Profit & Loss'!A41>=TODAY(), "Date: " & TEXT('Profit & Loss'!A41,"dd mmm yyy") & ", " & 'Profit & Loss'!B41 & CHAR(10) & "Time: " & TEXT('Profit & Loss'!C41, "hh:mm AM/PM") & " - " & TEXT('Profit & Loss'!D41, "hh:mm AM/PM") & CHAR(10) & "Venue: " & 'Profit & Loss'!E41 & CHAR(10) & "Court No.: " & 'Profit & Loss'!F41 & CHAR(10) & "Level: HB - LI" & CHAR(10) & "Please transfer $" & 'Profit & Loss'!O41 & " per pax to Belle (83396501)" & CHAR(10) & CHAR(10) & IF('Profit & Loss'!I41=1, "1." & CHAR(10) & "2." & CHAR(10) & "3." & CHAR(10) & "4." & CHAR(10) & "5." & CHAR(10) & "6." & CHAR(10), IF('Profit & Loss'!I41=2, "1." & CHAR(10) & "2." & CHAR(10) & "3." & CHAR(10) & "4." & CHAR(10) & "5." & CHAR(10) & "6." & CHAR(10) & "7." & CHAR(10) & "8." & CHAR(10) & "9." & CHAR(10) & "10." & CHAR(10) & "11." & CHAR(10) & "12." & CHAR(10), IF('Profit & Loss'!I41=3, "1." & CHAR(10) & "2." & CHAR(10) & "3." & CHAR(10) & "4." & CHAR(10) & "5." & CHAR(10) & "6." & CHAR(10) & "7." & CHAR(10) & "8." & CHAR(10) & "9." & CHAR(10) & "10." & CHAR(10) & "11." & CHAR(10) & "12." & CHAR(10) & "13." & CHAR(10) & "14." & CHAR(10) & "15." & CHAR(10) & "16." & CHAR(10) & "17." & CHAR(10) & "18." & CHAR(10), " ")))," ")
A39: =IF('Profit & Loss'!A42>=TODAY(),"Looking for friendly players to join the following game: " & CHAR(10) & CHAR(10) & "Date: " & TEXT('Profit & Loss'!A42,"dd mmm yyy") & ", " & 'Profit & Loss'!B42 & CHAR(10) & "Time: " & TEXT('Profit & Loss'!C42, "hh:mm AM/PM") & " - " & TEXT('Profit & Loss'!D42, "hh:mm AM/PM") & CHAR(10) & "Venue: " & 'Profit & Loss'!E42 & CHAR(10) & "Level: HB - LI" & CHAR(10) & "Cost: $" & 'Profit & Loss'!O42 & " per pax" & CHAR(10) & "Max " & 'Profit & Loss'!I42*6 & " pax," & " (" & 'Profit & Loss'!I42 & " courts)" & CHAR(10) & CHAR(10) & "RSL Ultimate shuttles provided" & CHAR(10) & CHAR(10) & "PM if interested, thank you!"," ") | B39: =IF('Profit & Loss'!A42>=TODAY(), "Date: " & TEXT('Profit & Loss'!A42,"dd mmm yyy") & ", " & 'Profit & Loss'!B42 & CHAR(10) & "Time: " & TEXT('Profit & Loss'!C42, "hh:mm AM/PM") & " - " & TEXT('Profit & Loss'!D42, "hh:mm AM/PM") & CHAR(10) & "Venue: " & 'Profit & Loss'!E42 & CHAR(10) & "Court No.: " & 'Profit & Loss'!F42 & CHAR(10) & "Level: HB - LI" & CHAR(10) & "Please transfer $" & 'Profit & Loss'!O42 & " per pax to Belle (83396501)" & CHAR(10) & CHAR(10) & IF('Profit & Loss'!I42=1, "1." & CHAR(10) & "2." & CHAR(10) & "3." & CHAR(10) & "4." & CHAR(10) & "5." & CHAR(10) & "6." & CHAR(10), IF('Profit & Loss'!I42=2, "1." & CHAR(10) & "2." & CHAR(10) & "3." & CHAR(10) & "4." & CHAR(10) & "5." & CHAR(10) & "6." & CHAR(10) & "7." & CHAR(10) & "8." & CHAR(10) & "9." & CHAR(10) & "10." & CHAR(10) & "11." & CHAR(10) & "12." & CHAR(10), IF('Profit & Loss'!I42=3, "1." & CHAR(10) & "2." & CHAR(10) & "3." & CHAR(10) & "4." & CHAR(10) & "5." & CHAR(10) & "6." & CHAR(10) & "7." & CHAR(10) & "8." & CHAR(10) & "9." & CHAR(10) & "10." & CHAR(10) & "11." & CHAR(10) & "12." & CHAR(10) & "13." & CHAR(10) & "14." & CHAR(10) & "15." & CHAR(10) & "16." & CHAR(10) & "17." & CHAR(10) & "18." & CHAR(10), " ")))," ")
A40: =IF('Profit & Loss'!A43>=TODAY(),"Looking for friendly players to join the following game: " & CHAR(10) & CHAR(10) & "Date: " & TEXT('Profit & Loss'!A43,"dd mmm yyy") & ", " & 'Profit & Loss'!B43 & CHAR(10) & "Time: " & TEXT('Profit & Loss'!C43, "hh:mm AM/PM") & " - " & TEXT('Profit & Loss'!D43, "hh:mm AM/PM") & CHAR(10) & "Venue: " & 'Profit & Loss'!E43 & CHAR(10) & "Level: HB - LI" & CHAR(10) & "Cost: $" & 'Profit & Loss'!O43 & " per pax" & CHAR(10) & "Max " & 'Profit & Loss'!I43*6 & " pax," & " (" & 'Profit & Loss'!I43 & " courts)" & CHAR(10) & CHAR(10) & "RSL Ultimate shuttles provided" & CHAR(10) & CHAR(10) & "PM if interested, thank you!"," ") | B40: =IF('Profit & Loss'!A43>=TODAY(), "Date: " & TEXT('Profit & Loss'!A43,"dd mmm yyy") & ", " & 'Profit & Loss'!B43 & CHAR(10) & "Time: " & TEXT('Profit & Loss'!C43, "hh:mm AM/PM") & " - " & TEXT('Profit & Loss'!D43, "hh:mm AM/PM") & CHAR(10) & "Venue: " & 'Profit & Loss'!E43 & CHAR(10) & "Court No.: " & 'Profit & Loss'!F43 & CHAR(10) & "Level: HB - LI" & CHAR(10) & "Please transfer $" & 'Profit & Loss'!O43 & " per pax to Belle (83396501)" & CHAR(10) & CHAR(10) & IF('Profit & Loss'!I43=1, "1." & CHAR(10) & "2." & CHAR(10) & "3." & CHAR(10) & "4." & CHAR(10) & "5." & CHAR(10) & "6." & CHAR(10), IF('Profit & Loss'!I43=2, "1." & CHAR(10) & "2." & CHAR(10) & "3." & CHAR(10) & "4." & CHAR(10) & "5." & CHAR(10) & "6." & CHAR(10) & "7." & CHAR(10) & "8." & CHAR(10) & "9." & CHAR(10) & "10." & CHAR(10) & "11." & CHAR(10) & "12." & CHAR(10), IF('Profit & Loss'!I43=3, "1." & CHAR(10) & "2." & CHAR(10) & "3." & CHAR(10) & "4." & CHAR(10) & "5." & CHAR(10) & "6." & CHAR(10) & "7." & CHAR(10) & "8." & CHAR(10) & "9." & CHAR(10) & "10." & CHAR(10) & "11." & CHAR(10) & "12." & CHAR(10) & "13." & CHAR(10) & "14." & CHAR(10) & "15." & CHAR(10) & "16." & CHAR(10) & "17." & CHAR(10) & "18." & CHAR(10), " ")))," ")
A41: =IF('Profit & Loss'!A44>=TODAY(),"Looking for friendly players to join the following game: " & CHAR(10) & CHAR(10) & "Date: " & TEXT('Profit & Loss'!A44,"dd mmm yyy") & ", " & 'Profit & Loss'!B44 & CHAR(10) & "Time: " & TEXT('Profit & Loss'!C44, "hh:mm AM/PM") & " - " & TEXT('Profit & Loss'!D44, "hh:mm AM/PM") & CHAR(10) & "Venue: " & 'Profit & Loss'!E44 & CHAR(10) & "Level: HB - LI" & CHAR(10) & "Cost: $" & 'Profit & Loss'!O44 & " per pax" & CHAR(10) & "Max " & 'Profit & Loss'!I44*6 & " pax," & " (" & 'Profit & Loss'!I44 & " courts)" & CHAR(10) & CHAR(10) & "RSL Ultimate shuttles provided" & CHAR(10) & CHAR(10) & "PM if interested, thank you!"," ") | B41: =IF('Profit & Loss'!A44>=TODAY(), "Date: " & TEXT('Profit & Loss'!A44,"dd mmm yyy") & ", " & 'Profit & Loss'!B44 & CHAR(10) & "Time: " & TEXT('Profit & Loss'!C44, "hh:mm AM/PM") & " - " & TEXT('Profit & Loss'!D44, "hh:mm AM/PM") & CHAR(10) & "Venue: " & 'Profit & Loss'!E44 & CHAR(10) & "Court No.: " & 'Profit & Loss'!F44 & CHAR(10) & "Level: HB - LI" & CHAR(10) & "Please transfer $" & 'Profit & Loss'!O44 & " per pax to Belle (83396501)" & CHAR(10) & CHAR(10) & IF('Profit & Loss'!I44=1, "1." & CHAR(10) & "2." & CHAR(10) & "3." & CHAR(10) & "4." & CHAR(10) & "5." & CHAR(10) & "6." & CHAR(10), IF('Profit & Loss'!I44=2, "1." & CHAR(10) & "2." & CHAR(10) & "3." & CHAR(10) & "4." & CHAR(10) & "5." & CHAR(10) & "6." & CHAR(10) & "7." & CHAR(10) & "8." & CHAR(10) & "9." & CHAR(10) & "10." & CHAR(10) & "11." & CHAR(10) & "12." & CHAR(10), IF('Profit & Loss'!I44=3, "1." & CHAR(10) & "2." & CHAR(10) & "3." & CHAR(10) & "4." & CHAR(10) & "5." & CHAR(10) & "6." & CHAR(10) & "7." & CHAR(10) & "8." & CHAR(10) & "9." & CHAR(10) & "10." & CHAR(10) & "11." & CHAR(10) & "12." & CHAR(10) & "13." & CHAR(10) & "14." & CHAR(10) & "15." & CHAR(10) & "16." & CHAR(10) & "17." & CHAR(10) & "18." & CHAR(10), " ")))," ")
A42: =IF('Profit & Loss'!A45>=TODAY(),"Looking for friendly players to join the following game: " & CHAR(10) & CHAR(10) & "Date: " & TEXT('Profit & Loss'!A45,"dd mmm yyy") & ", " & 'Profit & Loss'!B45 & CHAR(10) & "Time: " & TEXT('Profit & Loss'!C45, "hh:mm AM/PM") & " - " & TEXT('Profit & Loss'!D45, "hh:mm AM/PM") & CHAR(10) & "Venue: " & 'Profit & Loss'!E45 & CHAR(10) & "Level: HB - LI" & CHAR(10) & "Cost: $" & 'Profit & Loss'!O45 & " per pax" & CHAR(10) & "Max " & 'Profit & Loss'!I45*6 & " pax," & " (" & 'Profit & Loss'!I45 & " courts)" & CHAR(10) & CHAR(10) & "RSL Ultimate shuttles provided" & CHAR(10) & CHAR(10) & "PM if interested, thank you!"," ") | B42: =IF('Profit & Loss'!A45>=TODAY(), "Date: " & TEXT('Profit & Loss'!A45,"dd mmm yyy") & ", " & 'Profit & Loss'!B45 & CHAR(10) & "Time: " & TEXT('Profit & Loss'!C45, "hh:mm AM/PM") & " - " & TEXT('Profit & Loss'!D45, "hh:mm AM/PM") & CHAR(10) & "Venue: " & 'Profit & Loss'!E45 & CHAR(10) & "Court No.: " & 'Profit & Loss'!F45 & CHAR(10) & "Level: HB - LI" & CHAR(10) & "Please transfer $" & 'Profit & Loss'!O45 & " per pax to Belle (83396501)" & CHAR(10) & CHAR(10) & IF('Profit & Loss'!I45=1, "1." & CHAR(10) & "2." & CHAR(10) & "3." & CHAR(10) & "4." & CHAR(10) & "5." & CHAR(10) & "6." & CHAR(10), IF('Profit & Loss'!I45=2, "1." & CHAR(10) & "2." & CHAR(10) & "3." & CHAR(10) & "4." & CHAR(10) & "5." & CHAR(10) & "6." & CHAR(10) & "7." & CHAR(10) & "8." & CHAR(10) & "9." & CHAR(10) & "10." & CHAR(10) & "11." & CHAR(10) & "12." & CHAR(10), IF('Profit & Loss'!I45=3, "1." & CHAR(10) & "2." & CHAR(10) & "3." & CHAR(10) & "4." & CHAR(10) & "5." & CHAR(10) & "6." & CHAR(10) & "7." & CHAR(10) & "8." & CHAR(10) & "9." & CHAR(10) & "10." & CHAR(10) & "11." & CHAR(10) & "12." & CHAR(10) & "13." & CHAR(10) & "14." & CHAR(10) & "15." & CHAR(10) & "16." & CHAR(10) & "17." & CHAR(10) & "18." & CHAR(10), " ")))," ")
A43: =IF('Profit & Loss'!A46>=TODAY(),"Looking for friendly players to join the following game: " & CHAR(10) & CHAR(10) & "Date: " & TEXT('Profit & Loss'!A46,"dd mmm yyy") & ", " & 'Profit & Loss'!B46 & CHAR(10) & "Time: " & TEXT('Profit & Loss'!C46, "hh:mm AM/PM") & " - " & TEXT('Profit & Loss'!D46, "hh:mm AM/PM") & CHAR(10) & "Venue: " & 'Profit & Loss'!E46 & CHAR(10) & "Level: HB - LI" & CHAR(10) & "Cost: $" & 'Profit & Loss'!O46 & " per pax" & CHAR(10) & "Max " & 'Profit & Loss'!I46*6 & " pax," & " (" & 'Profit & Loss'!I46 & " courts)" & CHAR(10) & CHAR(10) & "RSL Ultimate shuttles provided" & CHAR(10) & CHAR(10) & "PM if interested, thank you!"," ") | B43: =IF('Profit & Loss'!A46>=TODAY(), "Date: " & TEXT('Profit & Loss'!A46,"dd mmm yyy") & ", " & 'Profit & Loss'!B46 & CHAR(10) & "Time: " & TEXT('Profit & Loss'!C46, "hh:mm AM/PM") & " - " & TEXT('Profit & Loss'!D46, "hh:mm AM/PM") & CHAR(10) & "Venue: " & 'Profit & Loss'!E46 & CHAR(10) & "Court No.: " & 'Profit & Loss'!F46 & CHAR(10) & "Level: HB - LI" & CHAR(10) & "Please transfer $" & 'Profit & Loss'!O46 & " per pax to Belle (83396501)" & CHAR(10) & CHAR(10) & IF('Profit & Loss'!I46=1, "1." & CHAR(10) & "2." & CHAR(10) & "3." & CHAR(10) & "4." & CHAR(10) & "5." & CHAR(10) & "6." & CHAR(10), IF('Profit & Loss'!I46=2, "1." & CHAR(10) & "2." & CHAR(10) & "3." & CHAR(10) & "4." & CHAR(10) & "5." & CHAR(10) & "6." & CHAR(10) & "7." & CHAR(10) & "8." & CHAR(10) & "9." & CHAR(10) & "10." & CHAR(10) & "11." & CHAR(10) & "12." & CHAR(10), IF('Profit & Loss'!I46=3, "1." & CHAR(10) & "2." & CHAR(10) & "3." & CHAR(10) & "4." & CHAR(10) & "5." & CHAR(10) & "6." & CHAR(10) & "7." & CHAR(10) & "8." & CHAR(10) & "9." & CHAR(10) & "10." & CHAR(10) & "11." & CHAR(10) & "12." & CHAR(10) & "13." & CHAR(10) & "14." & CHAR(10) & "15." & CHAR(10) & "16." & CHAR(10) & "17." & CHAR(10) & "18." & CHAR(10), " ")))," ")
A44: =IF('Profit & Loss'!A47>=TODAY(),"Looking for friendly players to join the following game: " & CHAR(10) & CHAR(10) & "Date: " & TEXT('Profit & Loss'!A47,"dd mmm yyy") & ", " & 'Profit & Loss'!B47 & CHAR(10) & "Time: " & TEXT('Profit & Loss'!C47, "hh:mm AM/PM") & " - " & TEXT('Profit & Loss'!D47, "hh:mm AM/PM") & CHAR(10) & "Venue: " & 'Profit & Loss'!E47 & CHAR(10) & "Level: HB - LI" & CHAR(10) & "Cost: $" & 'Profit & Loss'!O47 & " per pax" & CHAR(10) & "Max " & 'Profit & Loss'!I47*6 & " pax," & " (" & 'Profit & Loss'!I47 & " courts)" & CHAR(10) & CHAR(10) & "RSL Ultimate shuttles provided" & CHAR(10) & CHAR(10) & "PM if interested, thank you!"," ") | B44: =IF('Profit & Loss'!A47>=TODAY(), "Date: " & TEXT('Profit & Loss'!A47,"dd mmm yyy") & ", " & 'Profit & Loss'!B47 & CHAR(10) & "Time: " & TEXT('Profit & Loss'!C47, "hh:mm AM/PM") & " - " & TEXT('Profit & Loss'!D47, "hh:mm AM/PM") & CHAR(10) & "Venue: " & 'Profit & Loss'!E47 & CHAR(10) & "Court No.: " & 'Profit & Loss'!F47 & CHAR(10) & "Level: HB - LI" & CHAR(10) & "Please transfer $" & 'Profit & Loss'!O47 & " per pax to Belle (83396501)" & CHAR(10) & CHAR(10) & IF('Profit & Loss'!I47=1, "1." & CHAR(10) & "2." & CHAR(10) & "3." & CHAR(10) & "4." & CHAR(10) & "5." & CHAR(10) & "6." & CHAR(10), IF('Profit & Loss'!I47=2, "1." & CHAR(10) & "2." & CHAR(10) & "3." & CHAR(10) & "4." & CHAR(10) & "5." & CHAR(10) & "6." & CHAR(10) & "7." & CHAR(10) & "8." & CHAR(10) & "9." & CHAR(10) & "10." & CHAR(10) & "11." & CHAR(10) & "12." & CHAR(10), IF('Profit & Loss'!I47=3, "1." & CHAR(10) & "2." & CHAR(10) & "3." & CHAR(10) & "4." & CHAR(10) & "5." & CHAR(10) & "6." & CHAR(10) & "7." & CHAR(10) & "8." & CHAR(10) & "9." & CHAR(10) & "10." & CHAR(10) & "11." & CHAR(10) & "12." & CHAR(10) & "13." & CHAR(10) & "14." & CHAR(10) & "15." & CHAR(10) & "16." & CHAR(10) & "17." & CHAR(10) & "18." & CHAR(10), " ")))," ")
...

Sheet Profit & Loss
A1: Profit & Loss
A2: Starting Balance as at 23 Oct 2025 | C2: 61.71
G4: Court Details | K4: Shuttle Details | O4: Pub Details | R4: Members Details | U4: Per Game | Y4: Overall Funds
A5: Date | B5: Day | C5: Start Time | D5: End Time | E5: Location | F5: Court No. | G5: Court Cost ($ per hour) | H5: No. of Hours | I5: No. of Courts | J5: Total Court Cost ($) | K5: Shuttle Type | L5: No. of Shuttles Used | M5: Shuttle Cost ($ per shuttle) | N5: Total Shuttle Cost ($) | O5: Amount Paid by Pubs ($ per pax) | P5: No. of Pubs | Q5: Total Paid by Pubs ($) | R5: Amount Paid by Members ($) per pax) | S5: No. of Members | T5: Total Paid by Members ($) | U5: Total No. of Players | V5: Total Amount Received ($) | W5: Total Cost (Court + Shuttle $) | X5: Profit/Loss ($ per game) | Y5: Actual Earnings | Z5: In Flow (Pubs Joined) | AA5: Out Flow (Court Cost) | AB5: Out Flow (Shuttle Purchase) | AC5: Fund Balance Balance
A6: 45955 | B6: Sat | C6: 0.72916667 | D6: 0.8125 | E6: Siglap CC | G6: =VLOOKUP(E6,'Court List'!$A:$C,2,0) -> 18 | H6: 2 | I6: 2 | J6: =G6*(H6*I6) -> 72 | K6: Ultimate (Sep 2025) | L6: =SUM('Shuttle Count - Ultimate (Sep 2'!C6:F6) -> 11 | M6: =VLOOKUP(K6,'Shuttle Purchase'!A:C,3,0) -> 3.4458333 | N6: =L6*M6 -> 37.904167 | O6: =VLOOKUP(E6,'Court List'!$A:$C,3,0) -> 14 | P6: =COUNTIF('Pub List'!$C6:$T6,"<>") -> 8 | Q6: =O6*P6 -> 112 | S6: =COUNTIF('Member List'!$C6:$J6,"<>") -> 4 | U6: =P6+S6 -> 12 | V6: =Q6 -> 112 | W6: =J6+N6 -> 109.90417 | X6: =V6-W6 -> 2.0958333 | Y6: =C2+X6 -> 63.805833 | Z6: =V6 -> 112 | AA6: =-J6 -> -72 | AC6: =C2+Z6+AA6+AB6 -> 101.71
A7: 45960 | B7: Thurs | C7: 0.8125 | D7: 0.89583333 | E7: Kaki Bukit CC | G7: =VLOOKUP(E7,'Court List'!$A:$C,2,0) -> 6 | H7: 2 | I7: 1 | J7: =G7*(H7*I7) -> 12 | K7: Ultimate (Sep 2025) | L7: =SUM('Shuttle Count - Ultimate (Sep 2'!C7:F7) -> 5 | M7: =VLOOKUP(K7,'Shuttle Purchase'!A:C,3,0) -> 3.4458333 | N7: =L7*M7 -> 17.229167 | O7: =VLOOKUP(E7,'Court List'!$A:$C,3,0) -> 12 | P7: =COUNTIF('Pub List'!$C7:$T7,"<>") -> 3 | Q7: =O7*P7 -> 36 | S7: =COUNTIF('Member List'!$C7:$J7,"<>") -> 3 | U7: =P7+S7 -> 6 | V7: =Q7 -> 36 | W7: =J7+N7 -> 29.229167 | X7: =V7-W7 -> 6.7708333 | Y7: =Y6+X7 -> 70.576667 | Z7: =V7 -> 36 | AA7: =-J7 -> -12 | AC7: =AC6+Z7+AA7+AB7 -> 125.71
A8: 45963 | B8: Sun | C8: 0.8125 | D8: 0.89583333 | E8: Fengshan CC | G8: =VLOOKUP(E8,'Court List'!$A:$C,2,0) -> 8 | H8: 2 | I8: 2 | J8: =G8*(H8*I8) -> 32 | K8: Ultimate (Sep 2025) | L8: =SUM('Shuttle Count - Ultimate (Sep 2'!C8:F8) -> 11 | M8: =VLOOKUP(K8,'Shuttle Purchase'!A:C,3,0) -> 3.4458333 | N8: =L8*M8 -> 37.904167 | O8: =VLOOKUP(E8,'Court List'!$A:$C,3,0) -> 12 | P8: =COUNTIF('Pub List'!$C8:$T8,"<>") -> 7 | Q8: =O8*P8 -> 84 | S8: =COUNTIF('Member List'!$C8:$J8,"<>") -> 5 | U8: =P8+S8 -> 12 | V8: =Q8 -> 84 | W8: =J8+N8 -> 69.904167 | X8: =V8-W8 -> 14.095833 | Y8: =Y7+X8 -> 84.6725 | Z8: =V8 -> 84 | AA8: =-J8 -> -32 | AC8: =AC7+Z8+AA8+AB8 -> 177.71
A9: 45965 | B9: Tues | C9: 0.8125 | D9: 0.89583333 | E9: Kaki Bukit CC | G9: =VLOOKUP(E9,'Court List'!$A:$C,2,0) -> 6 | H9: 2 | I9: 1 | J9: =G9*(H9*I9) -> 12 | K9: Ultimate (Sep 2025) | L9: =SUM('Shuttle Count - Ultimate (Sep 2'!C9:F9) -> 3 | M9: =VLOOKUP(K9,'Shuttle Purchase'!A:C,3,0) -> 3.4458333 | N9: =L9*M9 -> 10.3375 | O9: =VLOOKUP(E9,'Court List'!$A:$C,3,0) -> 12 | P9: =COUNTIF('Pub List'!$C9:$T9,"<>") -> 1 | Q9: =O9*P9 -> 12 | S9: =COUNTIF('Member List'!$C9:$J9,"<>") -> 5 | U9: =P9+S9 -> 6 | V9: =Q9 -> 12 | W9: =J9+N9 -> 22.3375 | X9: =V9-W9 -> -10.3375 | Y9: =Y8+X9 -> 74.335 | Z9: =V9 -> 12 | AA9: =-J9 -> -12 | AC9: =AC8+Z9+AA9+AB9 -> 177.71
